Exception on /login [POST]
Traceback (most recent call last):
  File "C:\Users\wan\AppData\Roaming\Python\Python27\site-packages\flask\app.py", line 1817, in wsgi_app
    response = self.full_dispatch_request()
  File "C:\Users\wan\AppData\Roaming\Python\Python27\site-packages\flask\app.py", line 1477, in full_dispatch_request
    rv = self.handle_user_exception(e)
  File "C:\Users\wan\AppData\Roaming\Python\Python27\site-packages\flask\app.py", line 1381, in handle_user_exception
    reraise(exc_type, exc_value, tb)
  File "C:\Users\wan\AppData\Roaming\Python\Python27\site-packages\flask\app.py", line 1475, in full_dispatch_request
    rv = self.dispatch_request()
  File "C:\Users\wan\AppData\Roaming\Python\Python27\site-packages\flask\app.py", line 1461, in dispatch_request
    return self.view_functions[rule.endpoint](**req.view_args)
  File "contact.py", line 38, in login
    if user.path:
AttributeError: 'NoneType' object has no attribute 'path'
Invalid username xiangni or dasdasda password
Invalid username xiangni or dasdasda password
Invalid username xiangni or dasdasda password
error message The phone was sign up!please sign in
Exception on /login [POST]
Traceback (most recent call last):
  File "C:\Users\wan\AppData\Roaming\Python\Python27\site-packages\flask\app.py", line 1817, in wsgi_app
    response = self.full_dispatch_request()
  File "C:\Users\wan\AppData\Roaming\Python\Python27\site-packages\flask\app.py", line 1477, in full_dispatch_request
    rv = self.handle_user_exception(e)
  File "C:\Users\wan\AppData\Roaming\Python\Python27\site-packages\flask\app.py", line 1381, in handle_user_exception
    reraise(exc_type, exc_value, tb)
  File "C:\Users\wan\AppData\Roaming\Python\Python27\site-packages\flask\app.py", line 1475, in full_dispatch_request
    rv = self.dispatch_request()
  File "C:\Users\wan\AppData\Roaming\Python\Python27\site-packages\flask\app.py", line 1461, in dispatch_request
    return self.view_functions[rule.endpoint](**req.view_args)
  File "contact.py", line 38, in login
    if user.path:
AttributeError: 'User' object has no attribute 'path'
